[2023-10-25T06:22:39.254+0000] {logging_mixin.py:151} INFO - Changing /opt/***/logs/dag_id=pionada_etl/run_id=manual__2023-10-25T06:22:38.183182+00:00/task_id=fetch_data_from_source_db permission to 509
[2023-10-25T06:22:39.255+0000] {logging_mixin.py:151} INFO - Failed to change /opt/***/logs/dag_id=pionada_etl/run_id=manual__2023-10-25T06:22:38.183182+00:00/task_id=fetch_data_from_source_db permission to 509: [Errno 1] Operation not permitted: '/opt/***/logs/dag_id=pionada_etl/run_id=manual__2023-10-25T06:22:38.183182+00:00/task_id=fetch_data_from_source_db'
[2023-10-25T06:22:39.282+0000] {logging_mixin.py:151} INFO - Changing /opt/***/logs/dag_id=pionada_etl/run_id=manual__2023-10-25T06:22:38.183182+00:00/task_id=fetch_data_from_source_db permission to 509
[2023-10-25T06:22:39.283+0000] {logging_mixin.py:151} INFO - Failed to change /opt/***/logs/dag_id=pionada_etl/run_id=manual__2023-10-25T06:22:38.183182+00:00/task_id=fetch_data_from_source_db permission to 509: [Errno 1] Operation not permitted: '/opt/***/logs/dag_id=pionada_etl/run_id=manual__2023-10-25T06:22:38.183182+00:00/task_id=fetch_data_from_source_db'
[2023-10-25T06:22:39.307+0000] {taskinstance.py:1159} INFO - Dependencies all met for dep_context=non-requeueable deps ti=<TaskInstance: pionada_etl.fetch_data_from_source_db manual__2023-10-25T06:22:38.183182+00:00 [queued]>
[2023-10-25T06:22:39.315+0000] {taskinstance.py:1159} INFO - Dependencies all met for dep_context=requeueable deps ti=<TaskInstance: pionada_etl.fetch_data_from_source_db manual__2023-10-25T06:22:38.183182+00:00 [queued]>
[2023-10-25T06:22:39.316+0000] {taskinstance.py:1361} INFO - Starting attempt 1 of 2
[2023-10-25T06:22:39.327+0000] {taskinstance.py:1382} INFO - Executing <Task(PythonOperator): fetch_data_from_source_db> on 2023-10-25 06:22:38.183182+00:00
[2023-10-25T06:22:39.332+0000] {standard_task_runner.py:57} INFO - Started process 89 to run task
[2023-10-25T06:22:39.335+0000] {standard_task_runner.py:84} INFO - Running: ['***', 'tasks', 'run', 'pionada_etl', 'fetch_data_from_source_db', 'manual__2023-10-25T06:22:38.183182+00:00', '--job-id', '39', '--raw', '--subdir', 'DAGS_FOLDER/pionada_etl.py', '--cfg-path', '/tmp/tmpedl0nqgp']
[2023-10-25T06:22:39.338+0000] {standard_task_runner.py:85} INFO - Job 39: Subtask fetch_data_from_source_db
[2023-10-25T06:22:39.378+0000] {logging_mixin.py:151} INFO - Changing /opt/***/logs/dag_id=pionada_etl/run_id=manual__2023-10-25T06:22:38.183182+00:00/task_id=fetch_data_from_source_db permission to 509
[2023-10-25T06:22:39.379+0000] {logging_mixin.py:151} INFO - Failed to change /opt/***/logs/dag_id=pionada_etl/run_id=manual__2023-10-25T06:22:38.183182+00:00/task_id=fetch_data_from_source_db permission to 509: [Errno 1] Operation not permitted: '/opt/***/logs/dag_id=pionada_etl/run_id=manual__2023-10-25T06:22:38.183182+00:00/task_id=fetch_data_from_source_db'
[2023-10-25T06:22:39.381+0000] {task_command.py:416} INFO - Running <TaskInstance: pionada_etl.fetch_data_from_source_db manual__2023-10-25T06:22:38.183182+00:00 [running]> on host 84b7c80bed96
[2023-10-25T06:22:39.604+0000] {taskinstance.py:1662} INFO - Exporting env vars: AIRFLOW_CTX_DAG_OWNER='***' AIRFLOW_CTX_DAG_ID='pionada_etl' AIRFLOW_CTX_TASK_ID='fetch_data_from_source_db' AIRFLOW_CTX_EXECUTION_DATE='2023-10-25T06:22:38.183182+00:00' AIRFLOW_CTX_TRY_NUMBER='1' AIRFLOW_CTX_DAG_RUN_ID='manual__2023-10-25T06:22:38.183182+00:00'
[2023-10-25T06:22:47.613+0000] {taskinstance.py:1937} ERROR - Task failed with exception
Traceback (most recent call last):
  File "/home/airflow/.local/lib/python3.8/site-packages/sqlalchemy/engine/base.py", line 3371, in _wrap_pool_connect
    return fn()
  File "/home/airflow/.local/lib/python3.8/site-packages/sqlalchemy/pool/base.py", line 327, in connect
    return _ConnectionFairy._checkout(self)
  File "/home/airflow/.local/lib/python3.8/site-packages/sqlalchemy/pool/base.py", line 894, in _checkout
    fairy = _ConnectionRecord.checkout(pool)
  File "/home/airflow/.local/lib/python3.8/site-packages/sqlalchemy/pool/base.py", line 493, in checkout
    rec = pool._do_get()
  File "/home/airflow/.local/lib/python3.8/site-packages/sqlalchemy/pool/impl.py", line 146, in _do_get
    self._dec_overflow()
  File "/home/airflow/.local/lib/python3.8/site-packages/sqlalchemy/util/langhelpers.py", line 70, in __exit__
    compat.raise_(
  File "/home/airflow/.local/lib/python3.8/site-packages/sqlalchemy/util/compat.py", line 211, in raise_
    raise exception
  File "/home/airflow/.local/lib/python3.8/site-packages/sqlalchemy/pool/impl.py", line 143, in _do_get
    return self._create_connection()
  File "/home/airflow/.local/lib/python3.8/site-packages/sqlalchemy/pool/base.py", line 273, in _create_connection
    return _ConnectionRecord(self)
  File "/home/airflow/.local/lib/python3.8/site-packages/sqlalchemy/pool/base.py", line 388, in __init__
    self.__connect()
  File "/home/airflow/.local/lib/python3.8/site-packages/sqlalchemy/pool/base.py", line 691, in __connect
    pool.logger.debug("Error on connect(): %s", e)
  File "/home/airflow/.local/lib/python3.8/site-packages/sqlalchemy/util/langhelpers.py", line 70, in __exit__
    compat.raise_(
  File "/home/airflow/.local/lib/python3.8/site-packages/sqlalchemy/util/compat.py", line 211, in raise_
    raise exception
  File "/home/airflow/.local/lib/python3.8/site-packages/sqlalchemy/pool/base.py", line 686, in __connect
    self.dbapi_connection = connection = pool._invoke_creator(self)
  File "/home/airflow/.local/lib/python3.8/site-packages/sqlalchemy/engine/create.py", line 574, in connect
    return dialect.connect(*cargs, **cparams)
  File "/home/airflow/.local/lib/python3.8/site-packages/sqlalchemy/engine/default.py", line 598, in connect
    return self.dbapi.connect(*cargs, **cparams)
  File "/home/airflow/.local/lib/python3.8/site-packages/psycopg2/__init__.py", line 122, in connect
    conn = _connect(dsn, connection_factory=connection_factory, **kwasync)
psycopg2.OperationalError: could not translate host name "None" to address: Temporary failure in name resolution


The above exception was the direct cause of the following exception:

Traceback (most recent call last):
  File "/home/airflow/.local/lib/python3.8/site-packages/airflow/operators/python.py", line 192, in execute
    return_value = self.execute_callable()
  File "/home/airflow/.local/lib/python3.8/site-packages/airflow/operators/python.py", line 209, in execute_callable
    return self.python_callable(*self.op_args, **self.op_kwargs)
  File "/opt/airflow/dags/pionada_etl.py", line 48, in fetch_data_from_source_db
    df = pd.read_sql(f'SELECT * FROM {FETCH_TABLE_NAME}', source_engine)
  File "/home/airflow/.local/lib/python3.8/site-packages/pandas/io/sql.py", line 633, in read_sql
    with pandasSQL_builder(con) as pandas_sql:
  File "/home/airflow/.local/lib/python3.8/site-packages/pandas/io/sql.py", line 832, in pandasSQL_builder
    return SQLDatabase(con, schema, need_transaction)
  File "/home/airflow/.local/lib/python3.8/site-packages/pandas/io/sql.py", line 1539, in __init__
    con = self.exit_stack.enter_context(con.connect())
  File "/home/airflow/.local/lib/python3.8/site-packages/sqlalchemy/engine/base.py", line 3325, in connect
    return self._connection_cls(self, close_with_result=close_with_result)
  File "/home/airflow/.local/lib/python3.8/site-packages/sqlalchemy/engine/base.py", line 96, in __init__
    else engine.raw_connection()
  File "/home/airflow/.local/lib/python3.8/site-packages/sqlalchemy/engine/base.py", line 3404, in raw_connection
    return self._wrap_pool_connect(self.pool.connect, _connection)
  File "/home/airflow/.local/lib/python3.8/site-packages/sqlalchemy/engine/base.py", line 3374, in _wrap_pool_connect
    Connection._handle_dbapi_exception_noconnection(
  File "/home/airflow/.local/lib/python3.8/site-packages/sqlalchemy/engine/base.py", line 2208, in _handle_dbapi_exception_noconnection
    util.raise_(
  File "/home/airflow/.local/lib/python3.8/site-packages/sqlalchemy/util/compat.py", line 211, in raise_
    raise exception
  File "/home/airflow/.local/lib/python3.8/site-packages/sqlalchemy/engine/base.py", line 3371, in _wrap_pool_connect
    return fn()
  File "/home/airflow/.local/lib/python3.8/site-packages/sqlalchemy/pool/base.py", line 327, in connect
    return _ConnectionFairy._checkout(self)
  File "/home/airflow/.local/lib/python3.8/site-packages/sqlalchemy/pool/base.py", line 894, in _checkout
    fairy = _ConnectionRecord.checkout(pool)
  File "/home/airflow/.local/lib/python3.8/site-packages/sqlalchemy/pool/base.py", line 493, in checkout
    rec = pool._do_get()
  File "/home/airflow/.local/lib/python3.8/site-packages/sqlalchemy/pool/impl.py", line 146, in _do_get
    self._dec_overflow()
  File "/home/airflow/.local/lib/python3.8/site-packages/sqlalchemy/util/langhelpers.py", line 70, in __exit__
    compat.raise_(
  File "/home/airflow/.local/lib/python3.8/site-packages/sqlalchemy/util/compat.py", line 211, in raise_
    raise exception
  File "/home/airflow/.local/lib/python3.8/site-packages/sqlalchemy/pool/impl.py", line 143, in _do_get
    return self._create_connection()
  File "/home/airflow/.local/lib/python3.8/site-packages/sqlalchemy/pool/base.py", line 273, in _create_connection
    return _ConnectionRecord(self)
  File "/home/airflow/.local/lib/python3.8/site-packages/sqlalchemy/pool/base.py", line 388, in __init__
    self.__connect()
  File "/home/airflow/.local/lib/python3.8/site-packages/sqlalchemy/pool/base.py", line 691, in __connect
    pool.logger.debug("Error on connect(): %s", e)
  File "/home/airflow/.local/lib/python3.8/site-packages/sqlalchemy/util/langhelpers.py", line 70, in __exit__
    compat.raise_(
  File "/home/airflow/.local/lib/python3.8/site-packages/sqlalchemy/util/compat.py", line 211, in raise_
    raise exception
  File "/home/airflow/.local/lib/python3.8/site-packages/sqlalchemy/pool/base.py", line 686, in __connect
    self.dbapi_connection = connection = pool._invoke_creator(self)
  File "/home/airflow/.local/lib/python3.8/site-packages/sqlalchemy/engine/create.py", line 574, in connect
    return dialect.connect(*cargs, **cparams)
  File "/home/airflow/.local/lib/python3.8/site-packages/sqlalchemy/engine/default.py", line 598, in connect
    return self.dbapi.connect(*cargs, **cparams)
  File "/home/airflow/.local/lib/python3.8/site-packages/psycopg2/__init__.py", line 122, in connect
    conn = _connect(dsn, connection_factory=connection_factory, **kwasync)
sqlalchemy.exc.OperationalError: (psycopg2.OperationalError) could not translate host name "None" to address: Temporary failure in name resolution

(Background on this error at: https://sqlalche.me/e/14/e3q8)
[2023-10-25T06:22:47.626+0000] {taskinstance.py:1400} INFO - Marking task as UP_FOR_RETRY. dag_id=pionada_etl, task_id=fetch_data_from_source_db, execution_date=20231025T062238, start_date=20231025T062239, end_date=20231025T062247
[2023-10-25T06:22:47.641+0000] {standard_task_runner.py:104} ERROR - Failed to execute job 39 for task fetch_data_from_source_db ((psycopg2.OperationalError) could not translate host name "None" to address: Temporary failure in name resolution

(Background on this error at: https://sqlalche.me/e/14/e3q8); 89)
[2023-10-25T06:22:47.665+0000] {local_task_job_runner.py:228} INFO - Task exited with return code 1
[2023-10-25T06:22:47.814+0000] {taskinstance.py:2778} INFO - 0 downstream tasks scheduled from follow-on schedule check
