[2023-10-25T04:54:26.747+0000] {logging_mixin.py:151} INFO - Changing /opt/***/logs/dag_id=pionada_etl/run_id=manual__2023-10-25T04:54:23.167679+00:00/task_id=write_data_to_target_db permission to 509
[2023-10-25T04:54:26.748+0000] {logging_mixin.py:151} INFO - Failed to change /opt/***/logs/dag_id=pionada_etl/run_id=manual__2023-10-25T04:54:23.167679+00:00/task_id=write_data_to_target_db permission to 509: [Errno 1] Operation not permitted: '/opt/***/logs/dag_id=pionada_etl/run_id=manual__2023-10-25T04:54:23.167679+00:00/task_id=write_data_to_target_db'
[2023-10-25T04:54:26.778+0000] {logging_mixin.py:151} INFO - Changing /opt/***/logs/dag_id=pionada_etl/run_id=manual__2023-10-25T04:54:23.167679+00:00/task_id=write_data_to_target_db permission to 509
[2023-10-25T04:54:26.779+0000] {logging_mixin.py:151} INFO - Failed to change /opt/***/logs/dag_id=pionada_etl/run_id=manual__2023-10-25T04:54:23.167679+00:00/task_id=write_data_to_target_db permission to 509: [Errno 1] Operation not permitted: '/opt/***/logs/dag_id=pionada_etl/run_id=manual__2023-10-25T04:54:23.167679+00:00/task_id=write_data_to_target_db'
[2023-10-25T04:54:26.806+0000] {taskinstance.py:1159} INFO - Dependencies all met for dep_context=non-requeueable deps ti=<TaskInstance: pionada_etl.write_data_to_target_db manual__2023-10-25T04:54:23.167679+00:00 [queued]>
[2023-10-25T04:54:26.815+0000] {taskinstance.py:1159} INFO - Dependencies all met for dep_context=requeueable deps ti=<TaskInstance: pionada_etl.write_data_to_target_db manual__2023-10-25T04:54:23.167679+00:00 [queued]>
[2023-10-25T04:54:26.816+0000] {taskinstance.py:1361} INFO - Starting attempt 1 of 2
[2023-10-25T04:54:26.828+0000] {taskinstance.py:1382} INFO - Executing <Task(PythonOperator): write_data_to_target_db> on 2023-10-25 04:54:23.167679+00:00
[2023-10-25T04:54:26.833+0000] {standard_task_runner.py:57} INFO - Started process 555 to run task
[2023-10-25T04:54:26.837+0000] {standard_task_runner.py:84} INFO - Running: ['***', 'tasks', 'run', 'pionada_etl', 'write_data_to_target_db', 'manual__2023-10-25T04:54:23.167679+00:00', '--job-id', '18', '--raw', '--subdir', 'DAGS_FOLDER/pionada_etl.py', '--cfg-path', '/tmp/tmpjv3nm_2_']
[2023-10-25T04:54:26.840+0000] {standard_task_runner.py:85} INFO - Job 18: Subtask write_data_to_target_db
[2023-10-25T04:54:26.896+0000] {logging_mixin.py:151} INFO - Changing /opt/***/logs/dag_id=pionada_etl/run_id=manual__2023-10-25T04:54:23.167679+00:00/task_id=write_data_to_target_db permission to 509
[2023-10-25T04:54:26.897+0000] {logging_mixin.py:151} INFO - Failed to change /opt/***/logs/dag_id=pionada_etl/run_id=manual__2023-10-25T04:54:23.167679+00:00/task_id=write_data_to_target_db permission to 509: [Errno 1] Operation not permitted: '/opt/***/logs/dag_id=pionada_etl/run_id=manual__2023-10-25T04:54:23.167679+00:00/task_id=write_data_to_target_db'
[2023-10-25T04:54:26.899+0000] {task_command.py:416} INFO - Running <TaskInstance: pionada_etl.write_data_to_target_db manual__2023-10-25T04:54:23.167679+00:00 [running]> on host d181ed02477e
[2023-10-25T04:54:27.564+0000] {taskinstance.py:1662} INFO - Exporting env vars: AIRFLOW_CTX_DAG_OWNER='***' AIRFLOW_CTX_DAG_ID='pionada_etl' AIRFLOW_CTX_TASK_ID='write_data_to_target_db' AIRFLOW_CTX_EXECUTION_DATE='2023-10-25T04:54:23.167679+00:00' AIRFLOW_CTX_TRY_NUMBER='1' AIRFLOW_CTX_DAG_RUN_ID='manual__2023-10-25T04:54:23.167679+00:00'
[2023-10-25T04:54:27.655+0000] {taskinstance.py:1937} ERROR - Task failed with exception
Traceback (most recent call last):
  File "/home/airflow/.local/lib/python3.8/site-packages/sqlalchemy/engine/base.py", line 3371, in _wrap_pool_connect
    return fn()
  File "/home/airflow/.local/lib/python3.8/site-packages/sqlalchemy/pool/base.py", line 327, in connect
    return _ConnectionFairy._checkout(self)
  File "/home/airflow/.local/lib/python3.8/site-packages/sqlalchemy/pool/base.py", line 894, in _checkout
    fairy = _ConnectionRecord.checkout(pool)
  File "/home/airflow/.local/lib/python3.8/site-packages/sqlalchemy/pool/base.py", line 493, in checkout
    rec = pool._do_get()
  File "/home/airflow/.local/lib/python3.8/site-packages/sqlalchemy/pool/impl.py", line 146, in _do_get
    self._dec_overflow()
  File "/home/airflow/.local/lib/python3.8/site-packages/sqlalchemy/util/langhelpers.py", line 70, in __exit__
    compat.raise_(
  File "/home/airflow/.local/lib/python3.8/site-packages/sqlalchemy/util/compat.py", line 211, in raise_
    raise exception
  File "/home/airflow/.local/lib/python3.8/site-packages/sqlalchemy/pool/impl.py", line 143, in _do_get
    return self._create_connection()
  File "/home/airflow/.local/lib/python3.8/site-packages/sqlalchemy/pool/base.py", line 273, in _create_connection
    return _ConnectionRecord(self)
  File "/home/airflow/.local/lib/python3.8/site-packages/sqlalchemy/pool/base.py", line 388, in __init__
    self.__connect()
  File "/home/airflow/.local/lib/python3.8/site-packages/sqlalchemy/pool/base.py", line 691, in __connect
    pool.logger.debug("Error on connect(): %s", e)
  File "/home/airflow/.local/lib/python3.8/site-packages/sqlalchemy/util/langhelpers.py", line 70, in __exit__
    compat.raise_(
  File "/home/airflow/.local/lib/python3.8/site-packages/sqlalchemy/util/compat.py", line 211, in raise_
    raise exception
  File "/home/airflow/.local/lib/python3.8/site-packages/sqlalchemy/pool/base.py", line 686, in __connect
    self.dbapi_connection = connection = pool._invoke_creator(self)
  File "/home/airflow/.local/lib/python3.8/site-packages/sqlalchemy/engine/create.py", line 574, in connect
    return dialect.connect(*cargs, **cparams)
  File "/home/airflow/.local/lib/python3.8/site-packages/sqlalchemy/engine/default.py", line 598, in connect
    return self.dbapi.connect(*cargs, **cparams)
  File "/home/airflow/.local/lib/python3.8/site-packages/psycopg2/__init__.py", line 122, in connect
    conn = _connect(dsn, connection_factory=connection_factory, **kwasync)
psycopg2.OperationalError: connection to server at "localhost" (127.0.0.1), port 5432 failed: Connection refused
	Is the server running on that host and accepting TCP/IP connections?
connection to server at "localhost" (::1), port 5432 failed: Cannot assign requested address
	Is the server running on that host and accepting TCP/IP connections?


The above exception was the direct cause of the following exception:

Traceback (most recent call last):
  File "/home/airflow/.local/lib/python3.8/site-packages/airflow/operators/python.py", line 192, in execute
    return_value = self.execute_callable()
  File "/home/airflow/.local/lib/python3.8/site-packages/airflow/operators/python.py", line 209, in execute_callable
    return self.python_callable(*self.op_args, **self.op_kwargs)
  File "/opt/airflow/dags/pionada_etl.py", line 37, in write_data_to_target_db
    df.to_sql('pionada_test', target_engine, if_exists='replace', index=False)
  File "/home/airflow/.local/lib/python3.8/site-packages/pandas/core/generic.py", line 2878, in to_sql
    return sql.to_sql(
  File "/home/airflow/.local/lib/python3.8/site-packages/pandas/io/sql.py", line 768, in to_sql
    with pandasSQL_builder(con, schema=schema, need_transaction=True) as pandas_sql:
  File "/home/airflow/.local/lib/python3.8/site-packages/pandas/io/sql.py", line 832, in pandasSQL_builder
    return SQLDatabase(con, schema, need_transaction)
  File "/home/airflow/.local/lib/python3.8/site-packages/pandas/io/sql.py", line 1539, in __init__
    con = self.exit_stack.enter_context(con.connect())
  File "/home/airflow/.local/lib/python3.8/site-packages/sqlalchemy/engine/base.py", line 3325, in connect
    return self._connection_cls(self, close_with_result=close_with_result)
  File "/home/airflow/.local/lib/python3.8/site-packages/sqlalchemy/engine/base.py", line 96, in __init__
    else engine.raw_connection()
  File "/home/airflow/.local/lib/python3.8/site-packages/sqlalchemy/engine/base.py", line 3404, in raw_connection
    return self._wrap_pool_connect(self.pool.connect, _connection)
  File "/home/airflow/.local/lib/python3.8/site-packages/sqlalchemy/engine/base.py", line 3374, in _wrap_pool_connect
    Connection._handle_dbapi_exception_noconnection(
  File "/home/airflow/.local/lib/python3.8/site-packages/sqlalchemy/engine/base.py", line 2208, in _handle_dbapi_exception_noconnection
    util.raise_(
  File "/home/airflow/.local/lib/python3.8/site-packages/sqlalchemy/util/compat.py", line 211, in raise_
    raise exception
  File "/home/airflow/.local/lib/python3.8/site-packages/sqlalchemy/engine/base.py", line 3371, in _wrap_pool_connect
    return fn()
  File "/home/airflow/.local/lib/python3.8/site-packages/sqlalchemy/pool/base.py", line 327, in connect
    return _ConnectionFairy._checkout(self)
  File "/home/airflow/.local/lib/python3.8/site-packages/sqlalchemy/pool/base.py", line 894, in _checkout
    fairy = _ConnectionRecord.checkout(pool)
  File "/home/airflow/.local/lib/python3.8/site-packages/sqlalchemy/pool/base.py", line 493, in checkout
    rec = pool._do_get()
  File "/home/airflow/.local/lib/python3.8/site-packages/sqlalchemy/pool/impl.py", line 146, in _do_get
    self._dec_overflow()
  File "/home/airflow/.local/lib/python3.8/site-packages/sqlalchemy/util/langhelpers.py", line 70, in __exit__
    compat.raise_(
  File "/home/airflow/.local/lib/python3.8/site-packages/sqlalchemy/util/compat.py", line 211, in raise_
    raise exception
  File "/home/airflow/.local/lib/python3.8/site-packages/sqlalchemy/pool/impl.py", line 143, in _do_get
    return self._create_connection()
  File "/home/airflow/.local/lib/python3.8/site-packages/sqlalchemy/pool/base.py", line 273, in _create_connection
    return _ConnectionRecord(self)
  File "/home/airflow/.local/lib/python3.8/site-packages/sqlalchemy/pool/base.py", line 388, in __init__
    self.__connect()
  File "/home/airflow/.local/lib/python3.8/site-packages/sqlalchemy/pool/base.py", line 691, in __connect
    pool.logger.debug("Error on connect(): %s", e)
  File "/home/airflow/.local/lib/python3.8/site-packages/sqlalchemy/util/langhelpers.py", line 70, in __exit__
    compat.raise_(
  File "/home/airflow/.local/lib/python3.8/site-packages/sqlalchemy/util/compat.py", line 211, in raise_
    raise exception
  File "/home/airflow/.local/lib/python3.8/site-packages/sqlalchemy/pool/base.py", line 686, in __connect
    self.dbapi_connection = connection = pool._invoke_creator(self)
  File "/home/airflow/.local/lib/python3.8/site-packages/sqlalchemy/engine/create.py", line 574, in connect
    return dialect.connect(*cargs, **cparams)
  File "/home/airflow/.local/lib/python3.8/site-packages/sqlalchemy/engine/default.py", line 598, in connect
    return self.dbapi.connect(*cargs, **cparams)
  File "/home/airflow/.local/lib/python3.8/site-packages/psycopg2/__init__.py", line 122, in connect
    conn = _connect(dsn, connection_factory=connection_factory, **kwasync)
sqlalchemy.exc.OperationalError: (psycopg2.OperationalError) connection to server at "localhost" (127.0.0.1), port 5432 failed: Connection refused
	Is the server running on that host and accepting TCP/IP connections?
connection to server at "localhost" (::1), port 5432 failed: Cannot assign requested address
	Is the server running on that host and accepting TCP/IP connections?

(Background on this error at: https://sqlalche.me/e/14/e3q8)
[2023-10-25T04:54:27.673+0000] {taskinstance.py:1400} INFO - Marking task as UP_FOR_RETRY. dag_id=pionada_etl, task_id=write_data_to_target_db, execution_date=20231025T045423, start_date=20231025T045426, end_date=20231025T045427
[2023-10-25T04:54:27.687+0000] {standard_task_runner.py:104} ERROR - Failed to execute job 18 for task write_data_to_target_db ((psycopg2.OperationalError) connection to server at "localhost" (127.0.0.1), port 5432 failed: Connection refused
	Is the server running on that host and accepting TCP/IP connections?
connection to server at "localhost" (::1), port 5432 failed: Cannot assign requested address
	Is the server running on that host and accepting TCP/IP connections?

(Background on this error at: https://sqlalche.me/e/14/e3q8); 555)
[2023-10-25T04:54:27.734+0000] {local_task_job_runner.py:228} INFO - Task exited with return code 1
[2023-10-25T04:54:27.749+0000] {taskinstance.py:2778} INFO - 0 downstream tasks scheduled from follow-on schedule check
