[2023-10-25T04:36:22.799+0000] {logging_mixin.py:151} INFO - Changing /opt/***/logs/dag_id=pionada_etl/run_id=manual__2023-10-25T04:36:21.175521+00:00/task_id=fetch_data_from_source_db permission to 509
[2023-10-25T04:36:22.801+0000] {logging_mixin.py:151} INFO - Failed to change /opt/***/logs/dag_id=pionada_etl/run_id=manual__2023-10-25T04:36:21.175521+00:00/task_id=fetch_data_from_source_db permission to 509: [Errno 1] Operation not permitted: '/opt/***/logs/dag_id=pionada_etl/run_id=manual__2023-10-25T04:36:21.175521+00:00/task_id=fetch_data_from_source_db'
[2023-10-25T04:36:22.826+0000] {logging_mixin.py:151} INFO - Changing /opt/***/logs/dag_id=pionada_etl/run_id=manual__2023-10-25T04:36:21.175521+00:00/task_id=fetch_data_from_source_db permission to 509
[2023-10-25T04:36:22.827+0000] {logging_mixin.py:151} INFO - Failed to change /opt/***/logs/dag_id=pionada_etl/run_id=manual__2023-10-25T04:36:21.175521+00:00/task_id=fetch_data_from_source_db permission to 509: [Errno 1] Operation not permitted: '/opt/***/logs/dag_id=pionada_etl/run_id=manual__2023-10-25T04:36:21.175521+00:00/task_id=fetch_data_from_source_db'
[2023-10-25T04:36:22.855+0000] {taskinstance.py:1159} INFO - Dependencies all met for dep_context=non-requeueable deps ti=<TaskInstance: pionada_etl.fetch_data_from_source_db manual__2023-10-25T04:36:21.175521+00:00 [queued]>
[2023-10-25T04:36:22.863+0000] {taskinstance.py:1159} INFO - Dependencies all met for dep_context=requeueable deps ti=<TaskInstance: pionada_etl.fetch_data_from_source_db manual__2023-10-25T04:36:21.175521+00:00 [queued]>
[2023-10-25T04:36:22.864+0000] {taskinstance.py:1361} INFO - Starting attempt 1 of 2
[2023-10-25T04:36:22.879+0000] {taskinstance.py:1382} INFO - Executing <Task(PythonOperator): fetch_data_from_source_db> on 2023-10-25 04:36:21.175521+00:00
[2023-10-25T04:36:22.886+0000] {standard_task_runner.py:57} INFO - Started process 247 to run task
[2023-10-25T04:36:22.889+0000] {standard_task_runner.py:84} INFO - Running: ['***', 'tasks', 'run', 'pionada_etl', 'fetch_data_from_source_db', 'manual__2023-10-25T04:36:21.175521+00:00', '--job-id', '9', '--raw', '--subdir', 'DAGS_FOLDER/pionada_etl.py', '--cfg-path', '/tmp/tmp8684ju5c']
[2023-10-25T04:36:22.892+0000] {standard_task_runner.py:85} INFO - Job 9: Subtask fetch_data_from_source_db
[2023-10-25T04:36:22.940+0000] {logging_mixin.py:151} INFO - Changing /opt/***/logs/dag_id=pionada_etl/run_id=manual__2023-10-25T04:36:21.175521+00:00/task_id=fetch_data_from_source_db permission to 509
[2023-10-25T04:36:22.940+0000] {logging_mixin.py:151} INFO - Failed to change /opt/***/logs/dag_id=pionada_etl/run_id=manual__2023-10-25T04:36:21.175521+00:00/task_id=fetch_data_from_source_db permission to 509: [Errno 1] Operation not permitted: '/opt/***/logs/dag_id=pionada_etl/run_id=manual__2023-10-25T04:36:21.175521+00:00/task_id=fetch_data_from_source_db'
[2023-10-25T04:36:22.942+0000] {task_command.py:416} INFO - Running <TaskInstance: pionada_etl.fetch_data_from_source_db manual__2023-10-25T04:36:21.175521+00:00 [running]> on host d181ed02477e
[2023-10-25T04:36:23.188+0000] {taskinstance.py:1662} INFO - Exporting env vars: AIRFLOW_CTX_DAG_OWNER='***' AIRFLOW_CTX_DAG_ID='pionada_etl' AIRFLOW_CTX_TASK_ID='fetch_data_from_source_db' AIRFLOW_CTX_EXECUTION_DATE='2023-10-25T04:36:21.175521+00:00' AIRFLOW_CTX_TRY_NUMBER='1' AIRFLOW_CTX_DAG_RUN_ID='manual__2023-10-25T04:36:21.175521+00:00'
[2023-10-25T04:36:23.191+0000] {taskinstance.py:1937} ERROR - Task failed with exception
Traceback (most recent call last):
  File "/home/airflow/.local/lib/python3.8/site-packages/airflow/operators/python.py", line 192, in execute
    return_value = self.execute_callable()
  File "/home/airflow/.local/lib/python3.8/site-packages/airflow/operators/python.py", line 209, in execute_callable
    return self.python_callable(*self.op_args, **self.op_kwargs)
  File "/opt/airflow/dags/pionada_etl.py", line 28, in fetch_data_from_source_db
    source_engine = create_engine('database-pionada-ai-poc-13.cuerrc1vwpjd.ap-northeast-2.rds.amazonaws.com:5023/pionada_ai_poc_db')
  File "<string>", line 2, in create_engine
  File "/home/airflow/.local/lib/python3.8/site-packages/sqlalchemy/util/deprecations.py", line 375, in warned
    return fn(*args, **kwargs)
  File "/home/airflow/.local/lib/python3.8/site-packages/sqlalchemy/engine/create.py", line 514, in create_engine
    u = _url.make_url(url)
  File "/home/airflow/.local/lib/python3.8/site-packages/sqlalchemy/engine/url.py", line 738, in make_url
    return _parse_url(name_or_url)
  File "/home/airflow/.local/lib/python3.8/site-packages/sqlalchemy/engine/url.py", line 799, in _parse_url
    raise exc.ArgumentError(
sqlalchemy.exc.ArgumentError: Could not parse SQLAlchemy URL from string 'database-pionada-ai-poc-13.cuerrc1vwpjd.ap-northeast-2.rds.amazonaws.com:5023/pionada_ai_poc_db'
[2023-10-25T04:36:23.204+0000] {taskinstance.py:1400} INFO - Marking task as UP_FOR_RETRY. dag_id=pionada_etl, task_id=fetch_data_from_source_db, execution_date=20231025T043621, start_date=20231025T043622, end_date=20231025T043623
[2023-10-25T04:36:23.215+0000] {standard_task_runner.py:104} ERROR - Failed to execute job 9 for task fetch_data_from_source_db (Could not parse SQLAlchemy URL from string 'database-pionada-ai-poc-13.cuerrc1vwpjd.ap-northeast-2.rds.amazonaws.com:5023/pionada_ai_poc_db'; 247)
[2023-10-25T04:36:23.264+0000] {local_task_job_runner.py:228} INFO - Task exited with return code 1
[2023-10-25T04:36:23.293+0000] {taskinstance.py:2778} INFO - 0 downstream tasks scheduled from follow-on schedule check
